{
  "url": "https://api.github.com/repos/shap/shap/issues/1015",
  "repository_url": "https://api.github.com/repos/shap/shap",
  "labels_url": "https://api.github.com/repos/shap/shap/issues/1015/labels{/name}",
  "comments_url": "https://api.github.com/repos/shap/shap/issues/1015/comments",
  "events_url": "https://api.github.com/repos/shap/shap/issues/1015/events",
  "html_url": "https://github.com/shap/shap/issues/1015",
  "id": 554345009,
  "node_id": "MDU6SXNzdWU1NTQzNDUwMDk=",
  "number": 1015,
  "title": "DeepExplainer returns error as Explanations do not sum up to the model's output",
  "user": {
    "login": "chaupmcs",
    "id": 42042991,
    "node_id": "MDQ6VXNlcjQyMDQyOTkx",
    "avatar_url": "https://avatars.githubusercontent.com/u/42042991?v=4",
    "gravatar_id": "",
    "url": "https://api.github.com/users/chaupmcs",
    "html_url": "https://github.com/chaupmcs",
    "followers_url": "https://api.github.com/users/chaupmcs/followers",
    "following_url": "https://api.github.com/users/chaupmcs/following{/other_user}",
    "gists_url": "https://api.github.com/users/chaupmcs/gists{/gist_id}",
    "starred_url": "https://api.github.com/users/chaupmcs/starred{/owner}{/repo}",
    "subscriptions_url": "https://api.github.com/users/chaupmcs/subscriptions",
    "organizations_url": "https://api.github.com/users/chaupmcs/orgs",
    "repos_url": "https://api.github.com/users/chaupmcs/repos",
    "events_url": "https://api.github.com/users/chaupmcs/events{/privacy}",
    "received_events_url": "https://api.github.com/users/chaupmcs/received_events",
    "type": "User",
    "site_admin": false
  },
  "labels": [

  ],
  "state": "open",
  "locked": false,
  "assignee": null,
  "assignees": [

  ],
  "milestone": null,
  "comments": 5,
  "created_at": "2020-01-23T19:02:02Z",
  "updated_at": "2020-02-20T07:57:28Z",
  "closed_at": null,
  "author_association": "NONE",
  "active_lock_reason": null,
  "body": "I use **DeepExplainer** for stock data with LSTM.\r\nIt returns an error as **Explanations do not sum up to the model's output! Please post as a github issue**.\r\n\r\n> AssertionError              Traceback (most recent call last)\r\n<ipython-input-16-203dec3ae627> in <module>\r\n1   explainer = shap.DeepExplainer(model, X_train)\r\n----> 2    shap_values = explainer.shap_values(X_test)\r\n/opt/conda/lib/python3.6/site-packages/shap/explainers/deep/init.py in shap_values(self, X, ranked_outputs, output_rank_order)\r\n117         were chosen as \"top\".\r\n118         \"\"\"\r\n--> 119         return self.explainer.shap_values(X, ranked_outputs, output_rank_order)\r\n/opt/conda/lib/python3.6/site-packages/shap/explainers/deep/deep_tf.py in shap_values(self, X, ranked_outputs, output_rank_order, check_additivity)\r\n283             for l in range(len(X)):\r\n284                 diffs = model_output[:, l] - self.expected_value[l] - output_phis[l].sum(axis=tuple(range(1, output_phis[l].ndim)))\r\n--> 285                 assert np.abs(diffs).max() < 1e-4, \"Explanations do not sum up to the model's output! Please post as a github issue.\"\r\n286         if not self.multi_output:\r\n287             return output_phis[0]\r\nAssertionError: Explanations do not sum up to the model's output! Please post as a github issue.\r\n\r\nThe full source code here (including data, model): https://github.com/chaupmcs/DeepExplainerReturnsError/blob/master/DeepExplainer%20returns%20error%20with%20Stock%20data.ipynb\r\n\r\nThanks.",
  "closed_by": null,
  "reactions": {
    "url": "https://api.github.com/repos/shap/shap/issues/1015/reactions",
    "total_count": 0,
    "+1": 0,
    "-1": 0,
    "laugh": 0,
    "hooray": 0,
    "confused": 0,
    "heart": 0,
    "rocket": 0,
    "eyes": 0
  },
  "timeline_url": "https://api.github.com/repos/shap/shap/issues/1015/timeline",
  "performed_via_github_app": null,
  "state_reason": null
}
