{
  "url": "https://api.github.com/repos/shap/shap/issues/1226",
  "repository_url": "https://api.github.com/repos/shap/shap",
  "labels_url": "https://api.github.com/repos/shap/shap/issues/1226/labels{/name}",
  "comments_url": "https://api.github.com/repos/shap/shap/issues/1226/comments",
  "events_url": "https://api.github.com/repos/shap/shap/issues/1226/events",
  "html_url": "https://github.com/shap/shap/issues/1226",
  "id": 624220807,
  "node_id": "MDU6SXNzdWU2MjQyMjA4MDc=",
  "number": 1226,
  "title": "DeepExplainer yields 'NoneType' object cannot be interpreted as an integer",
  "user": {
    "login": "Martinhastrup",
    "id": 1333356,
    "node_id": "MDQ6VXNlcjEzMzMzNTY=",
    "avatar_url": "https://avatars.githubusercontent.com/u/1333356?v=4",
    "gravatar_id": "",
    "url": "https://api.github.com/users/Martinhastrup",
    "html_url": "https://github.com/Martinhastrup",
    "followers_url": "https://api.github.com/users/Martinhastrup/followers",
    "following_url": "https://api.github.com/users/Martinhastrup/following{/other_user}",
    "gists_url": "https://api.github.com/users/Martinhastrup/gists{/gist_id}",
    "starred_url": "https://api.github.com/users/Martinhastrup/starred{/owner}{/repo}",
    "subscriptions_url": "https://api.github.com/users/Martinhastrup/subscriptions",
    "organizations_url": "https://api.github.com/users/Martinhastrup/orgs",
    "repos_url": "https://api.github.com/users/Martinhastrup/repos",
    "events_url": "https://api.github.com/users/Martinhastrup/events{/privacy}",
    "received_events_url": "https://api.github.com/users/Martinhastrup/received_events",
    "type": "User",
    "site_admin": false
  },
  "labels": [

  ],
  "state": "open",
  "locked": false,
  "assignee": null,
  "assignees": [

  ],
  "milestone": null,
  "comments": 2,
  "created_at": "2020-05-25T10:52:00Z",
  "updated_at": "2020-08-27T11:54:24Z",
  "closed_at": null,
  "author_association": "NONE",
  "active_lock_reason": null,
  "body": "Trying to run the supplied [example ](https://slundberg.github.io/shap/notebooks/deep_explainer/Keras%20LSTM%20for%20IMDB%20Sentiment%20Classification.html)for shap on Keras LSTM for IMDB reviews, but when I try to run:\r\n\r\n```\r\nimport shap\r\nimport tensorflow as tf \r\n\r\nbackground = tf.convert_to_tensor(x_train[:100]) # Converting to Tensors, as required.\r\n# we use the first 100 training examples as our background dataset to integrate over\r\nexplainer = shap.DeepExplainer(model, background)\r\n\r\n# explain the first 10 predictions\r\n# explaining each prediction requires 2 * background dataset size runs\r\nshap_values = explainer.shap_values(x_test[:10])\r\n```\r\nI get the following error:\r\n```\r\n---------------------------------------------------------------------------\r\nTypeError                                 Traceback (most recent call last)\r\n<ipython-input-5-18cea8451462> in <module>\r\n      8 # explain the first 10 predictions\r\n      9 # explaining each prediction requires 2 * background dataset size runs\r\n---> 10 shap_values = explainer.shap_values(x_test[:10])\r\n\r\n/opt/conda/lib/python3.7/site-packages/shap/explainers/deep/__init__.py in shap_values(self, X, ranked_outputs, output_rank_order, check_additivity)\r\n    117         were chosen as \"top\".\r\n    118         \"\"\"\r\n--> 119         return self.explainer.shap_values(X, ranked_outputs, output_rank_order, check_additivity=check_additivity)\r\n\r\n/opt/conda/lib/python3.7/site-packages/shap/explainers/deep/deep_tf.py in shap_values(self, X, ranked_outputs, output_rank_order, check_additivity)\r\n    302                 # run attribution computation graph\r\n    303                 feature_ind = model_output_ranks[j,i]\r\n--> 304                 sample_phis = self.run(self.phi_symbolic(feature_ind), self.model_inputs, joint_input)\r\n    305 \r\n    306                 # assign the attributions to the right part of the output arrays\r\n\r\n/opt/conda/lib/python3.7/site-packages/shap/explainers/deep/deep_tf.py in run(self, out, model_inputs, X)\r\n    359 \r\n    360                 return final_out\r\n--> 361             return self.execute_with_overridden_gradients(anon)\r\n    362 \r\n    363     def custom_grad(self, op, *grads):\r\n\r\n/opt/conda/lib/python3.7/site-packages/shap/explainers/deep/deep_tf.py in execute_with_overridden_gradients(self, f)\r\n    395         # define the computation graph for the attribution values using a custom gradient-like computation\r\n    396         try:\r\n--> 397             out = f()\r\n    398         finally:\r\n    399             # reinstate the backpropagatable check\r\n\r\n/opt/conda/lib/python3.7/site-packages/shap/explainers/deep/deep_tf.py in anon()\r\n    352                     shape = list(self.model_inputs[i].shape)\r\n    353                     shape[0] = -1\r\n--> 354                     data = X[i].reshape(shape)\r\n    355                     v = tf.constant(data, dtype=self.model_inputs[i].dtype)\r\n    356                     inputs.append(v)\r\n\r\nTypeError: 'NoneType' object cannot be interpreted as an integer\r\n```\r\n\r\nI'm using: \r\nPython3\r\nshap==0.35\r\nTensorflow==2.20\r\n\r\nThe rest of the code is the same as in the example. Can you help? \r\n\r\nCheers",
  "closed_by": null,
  "reactions": {
    "url": "https://api.github.com/repos/shap/shap/issues/1226/reactions",
    "total_count": 1,
    "+1": 1,
    "-1": 0,
    "laugh": 0,
    "hooray": 0,
    "confused": 0,
    "heart": 0,
    "rocket": 0,
    "eyes": 0
  },
  "timeline_url": "https://api.github.com/repos/shap/shap/issues/1226/timeline",
  "performed_via_github_app": null,
  "state_reason": null
}
