{
  "url": "https://api.github.com/repos/shap/shap/issues/2574",
  "repository_url": "https://api.github.com/repos/shap/shap",
  "labels_url": "https://api.github.com/repos/shap/shap/issues/2574/labels{/name}",
  "comments_url": "https://api.github.com/repos/shap/shap/issues/2574/comments",
  "events_url": "https://api.github.com/repos/shap/shap/issues/2574/events",
  "html_url": "https://github.com/shap/shap/issues/2574",
  "id": 1259556192,
  "node_id": "I_kwDOBHDcK85LE01g",
  "number": 2574,
  "title": "Error with matplolib version 3.5.2 with dependence_plot",
  "user": {
    "login": "cparcerisas",
    "id": 46929065,
    "node_id": "MDQ6VXNlcjQ2OTI5MDY1",
    "avatar_url": "https://avatars.githubusercontent.com/u/46929065?v=4",
    "gravatar_id": "",
    "url": "https://api.github.com/users/cparcerisas",
    "html_url": "https://github.com/cparcerisas",
    "followers_url": "https://api.github.com/users/cparcerisas/followers",
    "following_url": "https://api.github.com/users/cparcerisas/following{/other_user}",
    "gists_url": "https://api.github.com/users/cparcerisas/gists{/gist_id}",
    "starred_url": "https://api.github.com/users/cparcerisas/starred{/owner}{/repo}",
    "subscriptions_url": "https://api.github.com/users/cparcerisas/subscriptions",
    "organizations_url": "https://api.github.com/users/cparcerisas/orgs",
    "repos_url": "https://api.github.com/users/cparcerisas/repos",
    "events_url": "https://api.github.com/users/cparcerisas/events{/privacy}",
    "received_events_url": "https://api.github.com/users/cparcerisas/received_events",
    "type": "User",
    "site_admin": false
  },
  "labels": [

  ],
  "state": "open",
  "locked": false,
  "assignee": null,
  "assignees": [

  ],
  "milestone": null,
  "comments": 0,
  "created_at": "2022-06-03T07:33:03Z",
  "updated_at": "2022-06-03T07:33:03Z",
  "closed_at": null,
  "author_association": "NONE",
  "active_lock_reason": null,
  "body": "When running dependence_plot it raises an error with the new version of matplotlib because in line 676 of _scatter.py the scatter plot is called with vmin, vmax and norm at the same time (before it was a warning but with the new matplotlib it became an error). \r\n   \r\n```\r\n        p = ax.scatter(\r\n            xv[xv_notnan], s[xv_notnan], s=dot_size, linewidth=0, c=cvals[xv_notnan],\r\n            cmap=cmap, alpha=alpha, vmin=clow, vmax=chigh,\r\n            norm=color_norm, rasterized=len(xv) > 500\r\n        )\r\n```\r\n\r\nshould become\r\n\r\n```\r\n      p = ax.scatter(\r\n          xv[xv_notnan], s[xv_notnan], s=dot_size, linewidth=0, c=cvals[xv_notnan],\r\n          cmap=cmap, alpha=alpha,\r\n          norm=color_norm, rasterized=len(xv) > 500\r\n      )\r\n```",
  "closed_by": null,
  "reactions": {
    "url": "https://api.github.com/repos/shap/shap/issues/2574/reactions",
    "total_count": 0,
    "+1": 0,
    "-1": 0,
    "laugh": 0,
    "hooray": 0,
    "confused": 0,
    "heart": 0,
    "rocket": 0,
    "eyes": 0
  },
  "timeline_url": "https://api.github.com/repos/shap/shap/issues/2574/timeline",
  "performed_via_github_app": null,
  "state_reason": null
}
