{
  "url": "https://api.github.com/repos/shap/shap/issues/941",
  "repository_url": "https://api.github.com/repos/shap/shap",
  "labels_url": "https://api.github.com/repos/shap/shap/issues/941/labels{/name}",
  "comments_url": "https://api.github.com/repos/shap/shap/issues/941/comments",
  "events_url": "https://api.github.com/repos/shap/shap/issues/941/events",
  "html_url": "https://github.com/shap/shap/issues/941",
  "id": 536678873,
  "node_id": "MDU6SXNzdWU1MzY2Nzg4NzM=",
  "number": 941,
  "title": "Additivity check failed in TreeExplainer",
  "user": {
    "login": "knaaptime",
    "id": 4213368,
    "node_id": "MDQ6VXNlcjQyMTMzNjg=",
    "avatar_url": "https://avatars.githubusercontent.com/u/4213368?v=4",
    "gravatar_id": "",
    "url": "https://api.github.com/users/knaaptime",
    "html_url": "https://github.com/knaaptime",
    "followers_url": "https://api.github.com/users/knaaptime/followers",
    "following_url": "https://api.github.com/users/knaaptime/following{/other_user}",
    "gists_url": "https://api.github.com/users/knaaptime/gists{/gist_id}",
    "starred_url": "https://api.github.com/users/knaaptime/starred{/owner}{/repo}",
    "subscriptions_url": "https://api.github.com/users/knaaptime/subscriptions",
    "organizations_url": "https://api.github.com/users/knaaptime/orgs",
    "repos_url": "https://api.github.com/users/knaaptime/repos",
    "events_url": "https://api.github.com/users/knaaptime/events{/privacy}",
    "received_events_url": "https://api.github.com/users/knaaptime/received_events",
    "type": "User",
    "site_admin": false
  },
  "labels": [

  ],
  "state": "closed",
  "locked": false,
  "assignee": null,
  "assignees": [

  ],
  "milestone": null,
  "comments": 11,
  "created_at": "2019-12-11T23:56:27Z",
  "updated_at": "2023-05-10T10:55:54Z",
  "closed_at": "2019-12-12T00:49:19Z",
  "author_association": "NONE",
  "active_lock_reason": null,
  "body": "Hi,\r\n\r\nthanks for the great package. I'm getting \r\n` AssertionError: Additivity check failed in TreeExplainer! Please report this on GitHub. Consider retrying with the feature_dependence='independent'` \r\n\r\nwhen trying to use `shap` in our [`package`](https://github.com/pysal/tobler) (you can see the error [here](https://travis-ci.com/knaaptime/tobler/jobs/266316023)). Everything has been working fine until this week, so i'm not totally sure where to go about troubleshooting, but it looks like this bug was newly introduced. Any thoughts?\r\n\r\nthanks again",
  "closed_by": {
    "login": "knaaptime",
    "id": 4213368,
    "node_id": "MDQ6VXNlcjQyMTMzNjg=",
    "avatar_url": "https://avatars.githubusercontent.com/u/4213368?v=4",
    "gravatar_id": "",
    "url": "https://api.github.com/users/knaaptime",
    "html_url": "https://github.com/knaaptime",
    "followers_url": "https://api.github.com/users/knaaptime/followers",
    "following_url": "https://api.github.com/users/knaaptime/following{/other_user}",
    "gists_url": "https://api.github.com/users/knaaptime/gists{/gist_id}",
    "starred_url": "https://api.github.com/users/knaaptime/starred{/owner}{/repo}",
    "subscriptions_url": "https://api.github.com/users/knaaptime/subscriptions",
    "organizations_url": "https://api.github.com/users/knaaptime/orgs",
    "repos_url": "https://api.github.com/users/knaaptime/repos",
    "events_url": "https://api.github.com/users/knaaptime/events{/privacy}",
    "received_events_url": "https://api.github.com/users/knaaptime/received_events",
    "type": "User",
    "site_admin": false
  },
  "reactions": {
    "url": "https://api.github.com/repos/shap/shap/issues/941/reactions",
    "total_count": 0,
    "+1": 0,
    "-1": 0,
    "laugh": 0,
    "hooray": 0,
    "confused": 0,
    "heart": 0,
    "rocket": 0,
    "eyes": 0
  },
  "timeline_url": "https://api.github.com/repos/shap/shap/issues/941/timeline",
  "performed_via_github_app": null,
  "state_reason": "completed"
}
